<sdf version='1.7'>
  <model name='robot_base'>
    <link name='base_link'>
      <inertial>
        <pose>0.003095 0 0.053305 0 -0 0</pose>
        <mass>47.873</mass>
        <inertia>
          <ixx>0.774277</ixx>
          <ixy>-1.03782e-10</ixy>
          <ixz>0.00763014</ixz>
          <iyy>1.64933</iyy>
          <iyz>1.09578e-12</iyz>
          <izz>2.12393</izz>
        </inertia>
      </inertial>
      <collision name='base_link_collision'>
        <pose>0 0 0 1.5708 -0 3.14</pose>
        <geometry>
          <mesh>
            <scale>1 1 1</scale>
            <uri>model://robot_description/meshes/robot_base.stl</uri>
          </mesh>
        </geometry>
      </collision>
      <visual name='base_link_visual'>
        <pose>0 0 0 1.5708 -0 3.14</pose>
        <geometry>
          <mesh>
            <scale>1 1 1</scale>
            <uri>model://robot_description/meshes/robot_base.stl</uri>
          </mesh>
        </geometry>
      </visual>
    </link>
    <joint name='front_left_wheel_joint' type='revolute'>
      <pose relative_to='base_link'>0.22 0.25 0 0 -0 0</pose>
      <parent>base_link</parent>
      <child>front_left_wheel</child>
      <axis>
        <xyz>0 1 0</xyz>
        <limit>
          <lower>-1e+16</lower>
          <upper>1e+16</upper>
        </limit>
        <dynamics>
          <spring_reference>0</spring_reference>
          <spring_stiffness>0</spring_stiffness>
        </dynamics>
      </axis>
    </joint>
    <link name='front_left_wheel'>
      <pose relative_to='front_left_wheel_joint'>0 0 0 0 -0 0</pose>
      <inertial>
        <pose>-0 0.006809 -0 0 -0 0</pose>
        <mass>2.6578</mass>
        <inertia>
          <ixx>0.00856503</ixx>
          <ixy>1.50741e-19</ixy>
          <ixz>-4.7815e-19</ixz>
          <iyy>0.0136706</iyy>
          <iyz>-2.68136e-19</iyz>
          <izz>0.00856503</izz>
        </inertia>
      </inertial>
      <collision name='front_left_wheel_collision'>
        <pose>0 0 0 1.5708 -0 0</pose>
        <geometry>
          <mesh>
            <scale>1 1 1</scale>
            <uri>model://robot_description/meshes/wheel.stl</uri>
          </mesh>
        </geometry>
        <surface>
          <contact>
            <ode>
              <kp>1e+07</kp>
              <kd>1</kd>
            </ode>
          </contact>
          <friction>
            <ode>
              <mu>1</mu>
              <mu2>1</mu2>
              <fdir1>1 0 0</fdir1>
            </ode>
          </friction>
        </surface>
      </collision>
      <visual name='front_left_wheel_visual'>
        <pose>0 0 0 1.5708 -0 0</pose>
        <geometry>
          <mesh>
            <scale>1 1 1</scale>
            <uri>model://robot_description/meshes/wheel.stl</uri>
          </mesh>
        </geometry>
      </visual>
    </link>
    <joint name='front_right_wheel_joint' type='revolute'>
      <pose relative_to='base_link'>0.22 -0.25 0 0 -0 0</pose>
      <parent>base_link</parent>
      <child>front_right_wheel</child>
      <axis>
        <xyz>0 1 0</xyz>
        <limit>
          <lower>-1e+16</lower>
          <upper>1e+16</upper>
        </limit>
        <dynamics>
          <spring_reference>0</spring_reference>
          <spring_stiffness>0</spring_stiffness>
        </dynamics>
      </axis>
    </joint>
    <link name='front_right_wheel'>
      <pose relative_to='front_right_wheel_joint'>0 0 0 0 -0 0</pose>
      <inertial>
        <pose>-0 0.006809 -0 0 -0 0</pose>
        <mass>2.6578</mass>
        <inertia>
          <ixx>0.00856503</ixx>
          <ixy>1.50741e-19</ixy>
          <ixz>-4.7815e-19</ixz>
          <iyy>0.0136706</iyy>
          <iyz>-2.68136e-19</iyz>
          <izz>0.00856503</izz>
        </inertia>
      </inertial>
      <collision name='front_right_wheel_collision'>
        <pose>0 0 0 1.5708 -0 0</pose>
        <geometry>
          <mesh>
            <scale>1 1 1</scale>
            <uri>model://robot_description/meshes/wheel.stl</uri>
          </mesh>
        </geometry>
        <surface>
          <contact>
            <ode>
              <kp>1e+07</kp>
              <kd>1</kd>
            </ode>
          </contact>
          <friction>
            <ode>
              <mu>1</mu>
              <mu2>1</mu2>
              <fdir1>1 0 0</fdir1>
            </ode>
          </friction>
        </surface>
      </collision>
      <visual name='front_right_wheel_visual'>
        <pose>0 0 0 1.5708 -0 0</pose>
        <geometry>
          <mesh>
            <scale>1 1 1</scale>
            <uri>model://robot_description/meshes/wheel.stl</uri>
          </mesh>
        </geometry>
      </visual>
    </link>
    <joint name='rear_left_wheel_joint' type='revolute'>
      <pose relative_to='base_link'>-0.22 0.25 0 0 -0 0</pose>
      <parent>base_link</parent>
      <child>rear_left_wheel</child>
      <axis>
        <xyz>0 1 0</xyz>
        <limit>
          <lower>-1e+16</lower>
          <upper>1e+16</upper>
        </limit>
        <dynamics>
          <spring_reference>0</spring_reference>
          <spring_stiffness>0</spring_stiffness>
        </dynamics>
      </axis>
    </joint>
    <link name='rear_left_wheel'>
      <pose relative_to='rear_left_wheel_joint'>0 0 0 0 -0 0</pose>
      <inertial>
        <pose>-0 0.006809 -0 0 -0 0</pose>
        <mass>2.6578</mass>
        <inertia>
          <ixx>0.00856503</ixx>
          <ixy>1.50741e-19</ixy>
          <ixz>-4.7815e-19</ixz>
          <iyy>0.0136706</iyy>
          <iyz>-2.68136e-19</iyz>
          <izz>0.00856503</izz>
        </inertia>
      </inertial>
      <collision name='rear_left_wheel_collision'>
        <pose>0 0 0 1.5708 -0 0</pose>
        <geometry>
          <mesh>
            <scale>1 1 1</scale>
            <uri>model://robot_description/meshes/wheel.stl</uri>
          </mesh>
        </geometry>
        <surface>
          <contact>
            <ode>
              <kp>1e+07</kp>
              <kd>1</kd>
            </ode>
          </contact>
          <friction>
            <ode>
              <mu>1</mu>
              <mu2>1</mu2>
              <fdir1>1 0 0</fdir1>
            </ode>
          </friction>
        </surface>
      </collision>
      <visual name='rear_left_wheel_visual'>
        <pose>0 0 0 1.5708 -0 0</pose>
        <geometry>
          <mesh>
            <scale>1 1 1</scale>
            <uri>model://robot_description/meshes/wheel.stl</uri>
          </mesh>
        </geometry>
      </visual>
    </link>
    <joint name='rear_right_wheel_joint' type='revolute'>
      <pose relative_to='base_link'>-0.22 -0.25 0 0 -0 0</pose>
      <parent>base_link</parent>
      <child>rear_right_wheel</child>
      <axis>
        <xyz>0 1 0</xyz>
        <limit>
          <lower>-1e+16</lower>
          <upper>1e+16</upper>
        </limit>
        <dynamics>
          <spring_reference>0</spring_reference>
          <spring_stiffness>0</spring_stiffness>
        </dynamics>
      </axis>
    </joint>
    <link name='rear_right_wheel'>
      <pose relative_to='rear_right_wheel_joint'>0 0 0 0 -0 0</pose>
      <inertial>
        <pose>-0 0.006809 -0 0 -0 0</pose>
        <mass>2.6578</mass>
        <inertia>
          <ixx>0.00856503</ixx>
          <ixy>1.50741e-19</ixy>
          <ixz>-4.7815e-19</ixz>
          <iyy>0.0136706</iyy>
          <iyz>-2.68136e-19</iyz>
          <izz>0.00856503</izz>
        </inertia>
      </inertial>
      <collision name='rear_right_wheel_collision'>
        <pose>0 0 0 1.5708 -0 0</pose>
        <geometry>
          <mesh>
            <scale>1 1 1</scale>
            <uri>model://robot_description/meshes/wheel.stl</uri>
          </mesh>
        </geometry>
      </collision>
      <visual name='rear_right_wheel_visual'>
        <pose>0 0 0 1.5708 -0 0</pose>
        <geometry>
          <mesh>
            <scale>1 1 1</scale>
            <uri>model://robot_description/meshes/wheel.stl</uri>
          </mesh>
        </geometry>
      </visual>
    </link>
    <plugin name='gazebo_ros_control' filename='libgazebo_ros_control.so'>
      <controlPeriod>0.001</controlPeriod>
      <legacyModeNS>0</legacyModeNS>
    </plugin>
    <static>0</static>
    <plugin name='diff_drive_controller' filename='libgazebo_ros_diff_drive.so'>
      <legacyMode>0</legacyMode>
      <alwaysOn>1</alwaysOn>
      <updateRate>1000.0</updateRate>
      <leftJoint>front_left_wheel_joint, rear_left_wheel_joint</leftJoint>
      <rightJoint>front_right_wheel_joint, rear_right_wheel_joint</rightJoint>
      <wheelSeparation>0.5</wheelSeparation>
      <wheelDiameter>0.2</wheelDiameter>
      <wheelTorque>10</wheelTorque>
      <publishTf>1</publishTf>
      <odometryFrame>map</odometryFrame>
      <commandTopic>cmd_vel</commandTopic>
      <odometryTopic>odom</odometryTopic>
      <robotBaseFrame>base_link</robotBaseFrame>
      <wheelAcceleration>2.8</wheelAcceleration>
      <publishWheelJointState>1</publishWheelJointState>
      <publishWheelTF>0</publishWheelTF>
      <odometrySource>world</odometrySource>
      <rosDebugLevel>Debug</rosDebugLevel>
    </plugin>
  </model>
</sdf>
